Workbook

Sheet Read Me
A1: Pulso Macro Tracker
A2: Your long-term written record — the Claude chat itself forgets once you close it, this doesn't.
A4: HOW TO USE
A5: 1. Targets tab: edit the blue cells (height, weight, goal weight, activity multiplier, deficit) if your stats change. Everything else recalculates.
A6: 2. Daily Log tab: each day, after your Claude coaching chat, copy the calorie/macro estimate into the matching date row. Dates are pre-filled through your goal window; row 2 is a filled-in EXAMPLE — overwrite it with your real first day.
A7: 3. Dashboard tab: your at-a-glance view — current stats, this week vs target, this month vs target, trend charts, and an auto-generated recommendation. Updates itself as you fill in the Daily Log.
A8: 4. Weekly Summary / Monthly Summary tabs: the tables the Dashboard's charts are built from — browse these for history beyond the current week/month.
A10: COLOR KEY
A11: Blue text = a cell you edit.
A12: Black text = a formula — don't overwrite, it will break the recalculation.
A13: Yellow fill = key assumption worth double-checking periodically.
A15: This is a personal coaching tool, not medical advice. Talk to a physician before starting or changing a sustained calorie deficit.

Sheet Dashboard
A1: Pulso Dashboard
A2: Auto-updates from the Daily Log. "This week" / "this month" track today's date automatically.
A4: internal: current week index | B4: =MIN(16,MAX(1,ROUNDUP((TODAY()-DATE(2026,8,9)+1)/7,0))) | C4: =this week's row in Weekly Summary | D4: =B4+1
A5: internal: current month index | B5: =MIN(5,MAX(1,(YEAR(TODAY())-2026)*12+MONTH(TODAY())-8+1)) | D5: =B5+1
A7: Weight | D7: This week vs target | G7: This month vs target
A8: Starting | B8: =Targets!$B$6 | D8: Avg calories | E8: =IFERROR(INDEX('Weekly Summary'!D:D,$D$4),"—") | G8: Avg weight change | H8: =IFERROR(INDEX('Monthly Summary'!C:C,$D$5),"—")
A9: Current (this week avg) | B9: =IFERROR(INDEX('Weekly Summary'!B:B,$D$4),"—") | D9: Calorie target | E9: =Targets!$B$12 | G9: Days logged | H9: =IFERROR(INDEX('Monthly Summary'!F:F,$D$5),0)
A10: Goal | B10: =Targets!$B$7 | D10: Avg protein (g) | E10: =IFERROR(INDEX('Weekly Summary'!E:E,$D$4),"—") | G10: Days on target (±100 kcal) | H10: =IFERROR(INDEX('Monthly Summary'!G:G,$D$5),0)
A11: Lbs lost so far | B11: =IFERROR(Targets!$B$6-INDEX('Weekly Summary'!B:B,$D$4),"—") | D11: Protein target (g) | E11: =Targets!$B$13 | G11: Pace to goal (weeks, from today) | H11: =Targets!$B$19
A12: Lbs to go | B12: =IFERROR(INDEX('Weekly Summary'!B:B,$D$4)-Targets!$B$7,"—") | D12: Weight change this week | E12: =IFERROR(INDEX('Weekly Summary'!C:C,$D$4),"—")
A14: Recommendation
A15: =IF(INDEX('Weekly Summary'!C:C,$D$4)="","Log at least a few days this week to get a recommendation.",IF(INDEX('Weekly Summary'!C:C,$D$4)<=-1.5,"Losing faster than target — consider adding back 100–150 kcal/day to protect muscle and energy.",IF(INDEX('Weekly Summary'!C:C,$D$4)<=-0.5,"On pace — keep current targets.",IF(INDEX('Weekly Summary'!C:C,$D$4)<0,"Slower than target — double check logging accuracy before cutting calories further.","No loss this week — check adherence first; if this repeats 2+ weeks, cut about 100–150 kcal/day."))))

Sheet Targets
A1: Targets
A2: Blue cells are inputs. Black cells recalculate automatically.
A4: Height (in) | B4: 68 | C4: 5'8"
A5: Age | B5: 61
A6: Starting weight (lb) | B6: 201 | C6: Update Daily Log for ongoing weigh-ins; this is the cut's starting point.
A7: Goal weight (lb) | B7: 187
A8: Activity multiplier | B8: 1.375 | C8: Sedentary desk job + resistance training every other day ≈ "lightly active" (Mifflin-St Jeor scale).
A9: BMR (kcal) | B9: =10*(B6*0.453592)+6.25*(B4*2.54)-5*B5+5 | C9: Mifflin-St Jeor equation.
A10: TDEE / maintenance (kcal) | B10: =B9*B8 | C10: BMR × activity multiplier.
A11: Target deficit (kcal/day) | B11: 500 | C11: ≈ 1 lb/week fat loss — sustainable pace while lifting every other day.
A12: Calorie target (kcal/day) | B12: =B10-B11
A13: Protein target (g/day) | B13: =ROUND(B7*1,0) | C13: ≈ 1g per lb of GOAL bodyweight — Attia/Lyon-style heuristic to preserve muscle during the cut.
A14: Fat target (g/day) | B14: =ROUND(B12*0.28/9,0) | C14: ≈ 28% of calories from fat.
A15: Carb target (g/day) | B15: =ROUND((B12-B13*4-B14*9)/4,0) | C15: Whatever calories remain after protein + fat.
A16: Fiber floor (g/day) | B16: 35 | C16: Elevated vs the standard 14g/1000kcal DV — Attia-style gut/metabolic health target.
A17: Added sugar ceiling (g/day) | B17: 25
A19: Pace to goal (weeks) | B19: =ROUND((B6-B7)/(B11/500),1) | C19: Weeks to goal, scaled from the 1 lb/week-per-500kcal-deficit rule (adjusts if you change the deficit above).

Sheet Daily Log
A1: Date | B1: Weight (lb) | C1: Calories | D1: Protein (g) | E1: Carbs (g) | F1: Fat (g) | G1: Fiber (g) | H1: Alcohol (kcal) | I1: Notes | J1: Cal vs Target | K1: Protein vs Target | L1: 7-day Avg Weight | M1: 7-day Avg Calories | N1: Waist (in)
A2: 46248 | B2: 201.4 | C2: 1820 | D2: 178 | E2: 138 | F2: 58 | G2: 32 | H2: 0 | I2: EXAMPLE ROW — overwrite with your real day | J2: =IF(C2="","",C2-Targets!$B$12) | K2: =IF(D2="","",D2-Targets!$B$13) | L2: =IFERROR(AVERAGEIFS($B$2:$B2,$A$2:$A2,">="&(A2-6),$A$2:$A2,"<="&A2),"") | M2: =IFERROR(AVERAGEIFS($C$2:$C2,$A$2:$A2,">="&(A2-6),$A$2:$A2,"<="&A2),"")
A3: 46249 | B3: 201 | C3: 1565 | D3: 114 | E3: 100 | F3: 74 | G3: 21 | H3: 0 | I3: Egg scramble (salmon, broccoli, cottage cheese); banana + peanut butter; NY strip (fat trimmed), sweet potato, arugula/avocado salad. Fat over budget (3 stacked sources), carbs starch-heavy. | J3: =IF(C3="","",C3-Targets!$B$12) | K3: =IF(D3="","",D3-Targets!$B$13) | L3: =IFERROR(AVERAGEIFS($B$2:$B3,$A$2:$A3,">="&(A3-6),$A$2:$A3,"<="&A3),"") | M3: =IFERROR(AVERAGEIFS($C$2:$C3,$A$2:$A3,">="&(A3-6),$A$2:$A3,"<="&A3),"")
A4: 46250 | C4: 845 | D4: 78 | E4: 23 | F4: 45 | G4: 2.5 | H4: 0 | I4: Latte; 2 hard-boiled eggs+smoked salmon+mango; whole branzino Mediterranean+broccoli. Travel day — light overall, protein/fiber well under target. | J4: =IF(C4="","",C4-Targets!$B$12) | K4: =IF(D4="","",D4-Targets!$B$13) | L4: =IFERROR(AVERAGEIFS($B$2:$B4,$A$2:$A4,">="&(A4-6),$A$2:$A4,"<="&A4),"") | M4: =IFERROR(AVERAGEIFS($C$2:$C4,$A$2:$A4,">="&(A4-6),$A$2:$A4,"<="&A4),"")
A5: 46251 | C5: 1500 | D5: 125 | E5: 107 | F5: 69 | G5: 19 | H5: 0 | I5: Late lunch 3:30p: Cuban lentejas (60%), grilled chicken w/ cream sauce, maduros. Dinner: 6oz filet mignon medium rare, grilled veg+broccoli. | J5: =IF(C5="","",C5-Targets!$B$12) | K5: =IF(D5="","",D5-Targets!$B$13) | L5: =IFERROR(AVERAGEIFS($B$2:$B5,$A$2:$A5,">="&(A5-6),$A$2:$A5,"<="&A5),"") | M5: =IFERROR(AVERAGEIFS($C$2:$C5,$A$2:$A5,">="&(A5-6),$A$2:$A5,"<="&A5),"")
A6: 46252 | C6: 1545 | D6: 107 | E6: 122 | F6: 68 | G6: 7 | H6: 0 | I6: Breakfast: 1 egg+2 egg whites (spinach, onion), pickled jalapenos, Oikos yogurt. Lunch ~2pm: grilled chicken chopped salad (blue cheese, walnuts, cranberries, vinaigrette). Dinner: Wendy's chicken sandwich no bun, 5 fries, medium sweet tea. Fat finished the day over target (68/57g, mostly cheese+nuts+fried chicken); protein came up short (107 of 187g) despite calories landing under budget (1545/1825) - a lean-but-low-protein day overall. | J6: =IF(C6="","",C6-Targets!$B$12) | K6: =IF(D6="","",D6-Targets!$B$13) | L6: =IFERROR(AVERAGEIFS($B$2:$B6,$A$2:$A6,">="&(A6-6),$A$2:$A6,"<="&A6),"") | M6: =IFERROR(AVERAGEIFS($C$2:$C6,$A$2:$A6,">="&(A6-6),$A$2:$A6,"<="&A6),"")
A7: 46253 | B7: 198 | C7: 1280 | D7: 101 | E7: 79 | F7: 67 | G7: 18 | I7: Weighed in 198.0 lb at 7am, waist 40in. Breakfast 8:19am: 213kcal/30g protein/5g carb/8g fat/1g fiber. Snack (work): 168kcal/19g protein/22g carb/2g fat/3g fiber. Lunch 2:12pm: 346kcal/24g protein/21g carb/20g fat/5g fiber. Dinner (photo, salad w/ avocado+eggs): 430kcal/20g protein/20g carb/32g fat/9g fiber. Latte (1 shot espresso, 2% milk, ~12oz): approx 123kcal/8g protein/11g carb/5g fat. Day total: 1,280kcal/101g protein/79g carb/67g fat/18g fiber. Fat now 10g over target (67/57g). Protein at 101g, still well under 187g target if the day is done. | J7: =IF(C7="","",C7-Targets!$B$12) | K7: =IF(D7="","",D7-Targets!$B$13) | L7: =IFERROR(AVERAGEIFS($B$2:$B7,$A$2:$A7,">="&(A7-6),$A$2:$A7,"<="&A7),"") | M7: =IFERROR(AVERAGEIFS($C$2:$C7,$A$2:$A7,">="&(A7-6),$A$2:$A7,"<="&A7),"") | N7: 40
A8: 46254 | C8: 1407 | D8: 147 | E8: 102 | F8: 46 | G8: 28 | H8: 0 | I8: Breakfast: 150g egg whites, 2 whole eggs, 50g spinach, 50g cottage cheese, salsa, blueberries (~130g), espresso no sugar - approx 373kcal/37g protein/27g carb/13g fat/5g fiber. Lunch: 180g salmon, 150g sweet potato, 145g brussels sprouts - approx 558kcal/46g protein/42g carb/22g fat/11g fiber. Dinner: turkey taco salad bowl - 175g extra-lean ground turkey, 75g arugula, 75g black beans, 75g pico de gallo, 40g avocado, 40g plain Greek yogurt, 25g white onion, cilantro+jalapeno, 1/2 lime - approx 476kcal/64g protein/33g carb/11g fat/12g fiber, gram-measured, excellent macro profile. Day total: 1,407kcal/147g protein/102g carb/46g fat/28g fiber - best day logged so far, well within every target with room to spare. | J8: =IF(C8="","",C8-Targets!$B$12) | K8: =IF(D8="","",D8-Targets!$B$13) | L8: =IFERROR(AVERAGEIFS($B$2:$B8,$A$2:$A8,">="&(A8-6),$A$2:$A8,"<="&A8),"") | M8: =IFERROR(AVERAGEIFS($C$2:$C8,$A$2:$A8,">="&(A8-6),$A$2:$A8,"<="&A8),"")
A9: 46255 | J9: =IF(C9="","",C9-Targets!$B$12) | K9: =IF(D9="","",D9-Targets!$B$13) | L9: =IFERROR(AVERAGEIFS($B$2:$B9,$A$2:$A9,">="&(A9-6),$A$2:$A9,"<="&A9),"") | M9: =IFERROR(AVERAGEIFS($C$2:$C9,$A$2:$A9,">="&(A9-6),$A$2:$A9,"<="&A9),"")
A10: 46256 | J10: =IF(C10="","",C10-Targets!$B$12) | K10: =IF(D10="","",D10-Targets!$B$13) | L10: =IFERROR(AVERAGEIFS($B$2:$B10,$A$2:$A10,">="&(A10-6),$A$2:$A10,"<="&A10),"") | M10: =IFERROR(AVERAGEIFS($C$2:$C10,$A$2:$A10,">="&(A10-6),$A$2:$A10,"<="&A10),"")
A11: 46257 | J11: =IF(C11="","",C11-Targets!$B$12) | K11: =IF(D11="","",D11-Targets!$B$13) | L11: =IFERROR(AVERAGEIFS($B$2:$B11,$A$2:$A11,">="&(A11-6),$A$2:$A11,"<="&A11),"") | M11: =IFERROR(AVERAGEIFS($C$2:$C11,$A$2:$A11,">="&(A11-6),$A$2:$A11,"<="&A11),"")
A12: 46258 | J12: =IF(C12="","",C12-Targets!$B$12) | K12: =IF(D12="","",D12-Targets!$B$13) | L12: =IFERROR(AVERAGEIFS($B$2:$B12,$A$2:$A12,">="&(A12-6),$A$2:$A12,"<="&A12),"") | M12: =IFERROR(AVERAGEIFS($C$2:$C12,$A$2:$A12,">="&(A12-6),$A$2:$A12,"<="&A12),"")
A13: 46259 | J13: =IF(C13="","",C13-Targets!$B$12) | K13: =IF(D13="","",D13-Targets!$B$13) | L13: =IFERROR(AVERAGEIFS($B$2:$B13,$A$2:$A13,">="&(A13-6),$A$2:$A13,"<="&A13),"") | M13: =IFERROR(AVERAGEIFS($C$2:$C13,$A$2:$A13,">="&(A13-6),$A$2:$A13,"<="&A13),"")
A14: 46260 | J14: =IF(C14="","",C14-Targets!$B$12) | K14: =IF(D14="","",D14-Targets!$B$13) | L14: =IFERROR(AVERAGEIFS($B$2:$B14,$A$2:$A14,">="&(A14-6),$A$2:$A14,"<="&A14),"") | M14: =IFERROR(AVERAGEIFS($C$2:$C14,$A$2:$A14,">="&(A14-6),$A$2:$A14,"<="&A14),"")
A15: 46261 | J15: =IF(C15="","",C15-Targets!$B$12) | K15: =IF(D15="","",D15-Targets!$B$13) | L15: =IFERROR(AVERAGEIFS($B$2:$B15,$A$2:$A15,">="&(A15-6),$A$2:$A15,"<="&A15),"") | M15: =IFERROR(AVERAGEIFS($C$2:$C15,$A$2:$A15,">="&(A15-6),$A$2:$A15,"<="&A15),"")
A16: 46262 | J16: =IF(C16="","",C16-Targets!$B$12) | K16: =IF(D16="","",D16-Targets!$B$13) | L16: =IFERROR(AVERAGEIFS($B$2:$B16,$A$2:$A16,">="&(A16-6),$A$2:$A16,"<="&A16),"") | M16: =IFERROR(AVERAGEIFS($C$2:$C16,$A$2:$A16,">="&(A16-6),$A$2:$A16,"<="&A16),"")
A17: 46263 | J17: =IF(C17="","",C17-Targets!$B$12) | K17: =IF(D17="","",D17-Targets!$B$13) | L17: =IFERROR(AVERAGEIFS($B$2:$B17,$A$2:$A17,">="&(A17-6),$A$2:$A17,"<="&A17),"") | M17: =IFERROR(AVERAGEIFS($C$2:$C17,$A$2:$A17,">="&(A17-6),$A$2:$A17,"<="&A17),"")
A18: 46264 | J18: =IF(C18="","",C18-Targets!$B$12) | K18: =IF(D18="","",D18-Targets!$B$13) | L18: =IFERROR(AVERAGEIFS($B$2:$B18,$A$2:$A18,">="&(A18-6),$A$2:$A18,"<="&A18),"") | M18: =IFERROR(AVERAGEIFS($C$2:$C18,$A$2:$A18,">="&(A18-6),$A$2:$A18,"<="&A18),"")
A19: 46265 | J19: =IF(C19="","",C19-Targets!$B$12) | K19: =IF(D19="","",D19-Targets!$B$13) | L19: =IFERROR(AVERAGEIFS($B$2:$B19,$A$2:$A19,">="&(A19-6),$A$2:$A19,"<="&A19),"") | M19: =IFERROR(AVERAGEIFS($C$2:$C19,$A$2:$A19,">="&(A19-6),$A$2:$A19,"<="&A19),"")
A20: 46266 | J20: =IF(C20="","",C20-Targets!$B$12) | K20: =IF(D20="","",D20-Targets!$B$13) | L20: =IFERROR(AVERAGEIFS($B$2:$B20,$A$2:$A20,">="&(A20-6),$A$2:$A20,"<="&A20),"") | M20: =IFERROR(AVERAGEIFS($C$2:$C20,$A$2:$A20,">="&(A20-6),$A$2:$A20,"<="&A20),"")
... A114: 46360 | J114: =IF(C114="","",C114-Targets!$B$12) | K114: =IF(D114="","",D114-Targets!$B$13) | L114: =IFERROR(AVERAGEIFS($B$2:$B114,$A$2:$A114,">="&(A114-6),$A$2:$A114,"<="&A114),"") | M114: =IFERROR(AVERAGEIFS($C$2:$C114,$A$2:$A114,">="&(A114-6),$A$2:$A114,"<="&A114),"")

Sheet Weekly Summary
A1: Week Start | B1: Avg Weight (lb) | C1: Weight Change vs Prior Week | D1: Avg Calories | E1: Avg Protein (g) | F1: On Pace? (target ≈1 lb/wk loss) | G1: Goal Weight (ref) | H1: Calorie Target (ref) | I1: Protein Target (ref)
A2: 46243 | B2: =IFERROR(AVERAGEIFS('Daily Log'!$B$2:$B$114,'Daily Log'!$A$2:$A$114,">="&A2,'Daily Log'!$A$2:$A$114,"<"&(A2+7)),"") | D2: =IFERROR(AVERAGEIFS('Daily Log'!$C$2:$C$114,'Daily Log'!$A$2:$A$114,">="&A2,'Daily Log'!$A$2:$A$114,"<"&(A2+7)),"") | E2: =IFERROR(AVERAGEIFS('Daily Log'!$D$2:$D$114,'Daily Log'!$A$2:$A$114,">="&A2,'Daily Log'!$A$2:$A$114,"<"&(A2+7)),"") | G2: =Targets!$B$7 | H2: =Targets!$B$12 | I2: =Targets!$B$13
A3: 46250 | B3: =IFERROR(AVERAGEIFS('Daily Log'!$B$2:$B$114,'Daily Log'!$A$2:$A$114,">="&A3,'Daily Log'!$A$2:$A$114,"<"&(A3+7)),"") | C3: =IF(OR(B3="",B2=""),"",B3-B2) | D3: =IFERROR(AVERAGEIFS('Daily Log'!$C$2:$C$114,'Daily Log'!$A$2:$A$114,">="&A3,'Daily Log'!$A$2:$A$114,"<"&(A3+7)),"") | E3: =IFERROR(AVERAGEIFS('Daily Log'!$D$2:$D$114,'Daily Log'!$A$2:$A$114,">="&A3,'Daily Log'!$A$2:$A$114,"<"&(A3+7)),"") | F3: =IF(C3="","",IF(C3<=-0.5,"On pace",IF(C3>0,"Check adherence","Slower than target"))) | G3: =Targets!$B$7 | H3: =Targets!$B$12 | I3: =Targets!$B$13
A4: 46257 | B4: =IFERROR(AVERAGEIFS('Daily Log'!$B$2:$B$114,'Daily Log'!$A$2:$A$114,">="&A4,'Daily Log'!$A$2:$A$114,"<"&(A4+7)),"") | C4: =IF(OR(B4="",B3=""),"",B4-B3) | D4: =IFERROR(AVERAGEIFS('Daily Log'!$C$2:$C$114,'Daily Log'!$A$2:$A$114,">="&A4,'Daily Log'!$A$2:$A$114,"<"&(A4+7)),"") | E4: =IFERROR(AVERAGEIFS('Daily Log'!$D$2:$D$114,'Daily Log'!$A$2:$A$114,">="&A4,'Daily Log'!$A$2:$A$114,"<"&(A4+7)),"") | F4: =IF(C4="","",IF(C4<=-0.5,"On pace",IF(C4>0,"Check adherence","Slower than target"))) | G4: =Targets!$B$7 | H4: =Targets!$B$12 | I4: =Targets!$B$13
A5: 46264 | B5: =IFERROR(AVERAGEIFS('Daily Log'!$B$2:$B$114,'Daily Log'!$A$2:$A$114,">="&A5,'Daily Log'!$A$2:$A$114,"<"&(A5+7)),"") | C5: =IF(OR(B5="",B4=""),"",B5-B4) | D5: =IFERROR(AVERAGEIFS('Daily Log'!$C$2:$C$114,'Daily Log'!$A$2:$A$114,">="&A5,'Daily Log'!$A$2:$A$114,"<"&(A5+7)),"") | E5: =IFERROR(AVERAGEIFS('Daily Log'!$D$2:$D$114,'Daily Log'!$A$2:$A$114,">="&A5,'Daily Log'!$A$2:$A$114,"<"&(A5+7)),"") | F5: =IF(C5="","",IF(C5<=-0.5,"On pace",IF(C5>0,"Check adherence","Slower than target"))) | G5: =Targets!$B$7 | H5: =Targets!$B$12 | I5: =Targets!$B$13
A6: 46271 | B6: =IFERROR(AVERAGEIFS('Daily Log'!$B$2:$B$114,'Daily Log'!$A$2:$A$114,">="&A6,'Daily Log'!$A$2:$A$114,"<"&(A6+7)),"") | C6: =IF(OR(B6="",B5=""),"",B6-B5) | D6: =IFERROR(AVERAGEIFS('Daily Log'!$C$2:$C$114,'Daily Log'!$A$2:$A$114,">="&A6,'Daily Log'!$A$2:$A$114,"<"&(A6+7)),"") | E6: =IFERROR(AVERAGEIFS('Daily Log'!$D$2:$D$114,'Daily Log'!$A$2:$A$114,">="&A6,'Daily Log'!$A$2:$A$114,"<"&(A6+7)),"") | F6: =IF(C6="","",IF(C6<=-0.5,"On pace",IF(C6>0,"Check adherence","Slower than target"))) | G6: =Targets!$B$7 | H6: =Targets!$B$12 | I6: =Targets!$B$13
A7: 46278 | B7: =IFERROR(AVERAGEIFS('Daily Log'!$B$2:$B$114,'Daily Log'!$A$2:$A$114,">="&A7,'Daily Log'!$A$2:$A$114,"<"&(A7+7)),"") | C7: =IF(OR(B7="",B6=""),"",B7-B6) | D7: =IFERROR(AVERAGEIFS('Daily Log'!$C$2:$C$114,'Daily Log'!$A$2:$A$114,">="&A7,'Daily Log'!$A$2:$A$114,"<"&(A7+7)),"") | E7: =IFERROR(AVERAGEIFS('Daily Log'!$D$2:$D$114,'Daily Log'!$A$2:$A$114,">="&A7,'Daily Log'!$A$2:$A$114,"<"&(A7+7)),"") | F7: =IF(C7="","",IF(C7<=-0.5,"On pace",IF(C7>0,"Check adherence","Slower than target"))) | G7: =Targets!$B$7 | H7: =Targets!$B$12 | I7: =Targets!$B$13
A8: 46285 | B8: =IFERROR(AVERAGEIFS('Daily Log'!$B$2:$B$114,'Daily Log'!$A$2:$A$114,">="&A8,'Daily Log'!$A$2:$A$114,"<"&(A8+7)),"") | C8: =IF(OR(B8="",B7=""),"",B8-B7) | D8: =IFERROR(AVERAGEIFS('Daily Log'!$C$2:$C$114,'Daily Log'!$A$2:$A$114,">="&A8,'Daily Log'!$A$2:$A$114,"<"&(A8+7)),"") | E8: =IFERROR(AVERAGEIFS('Daily Log'!$D$2:$D$114,'Daily Log'!$A$2:$A$114,">="&A8,'Daily Log'!$A$2:$A$114,"<"&(A8+7)),"") | F8: =IF(C8="","",IF(C8<=-0.5,"On pace",IF(C8>0,"Check adherence","Slower than target"))) | G8: =Targets!$B$7 | H8: =Targets!$B$12 | I8: =Targets!$B$13
A9: 46292 | B9: =IFERROR(AVERAGEIFS('Daily Log'!$B$2:$B$114,'Daily Log'!$A$2:$A$114,">="&A9,'Daily Log'!$A$2:$A$114,"<"&(A9+7)),"") | C9: =IF(OR(B9="",B8=""),"",B9-B8) | D9: =IFERROR(AVERAGEIFS('Daily Log'!$C$2:$C$114,'Daily Log'!$A$2:$A$114,">="&A9,'Daily Log'!$A$2:$A$114,"<"&(A9+7)),"") | E9: =IFERROR(AVERAGEIFS('Daily Log'!$D$2:$D$114,'Daily Log'!$A$2:$A$114,">="&A9,'Daily Log'!$A$2:$A$114,"<"&(A9+7)),"") | F9: =IF(C9="","",IF(C9<=-0.5,"On pace",IF(C9>0,"Check adherence","Slower than target"))) | G9: =Targets!$B$7 | H9: =Targets!$B$12 | I9: =Targets!$B$13
A10: 46299 | B10: =IFERROR(AVERAGEIFS('Daily Log'!$B$2:$B$114,'Daily Log'!$A$2:$A$114,">="&A10,'Daily Log'!$A$2:$A$114,"<"&(A10+7)),"") | C10: =IF(OR(B10="",B9=""),"",B10-B9) | D10: =IFERROR(AVERAGEIFS('Daily Log'!$C$2:$C$114,'Daily Log'!$A$2:$A$114,">="&A10,'Daily Log'!$A$2:$A$114,"<"&(A10+7)),"") | E10: =IFERROR(AVERAGEIFS('Daily Log'!$D$2:$D$114,'Daily Log'!$A$2:$A$114,">="&A10,'Daily Log'!$A$2:$A$114,"<"&(A10+7)),"") | F10: =IF(C10="","",IF(C10<=-0.5,"On pace",IF(C10>0,"Check adherence","Slower than target"))) | G10: =Targets!$B$7 | H10: =Targets!$B$12 | I10: =Targets!$B$13
A11: 46306 | B11: =IFERROR(AVERAGEIFS('Daily Log'!$B$2:$B$114,'Daily Log'!$A$2:$A$114,">="&A11,'Daily Log'!$A$2:$A$114,"<"&(A11+7)),"") | C11: =IF(OR(B11="",B10=""),"",B11-B10) | D11: =IFERROR(AVERAGEIFS('Daily Log'!$C$2:$C$114,'Daily Log'!$A$2:$A$114,">="&A11,'Daily Log'!$A$2:$A$114,"<"&(A11+7)),"") | E11: =IFERROR(AVERAGEIFS('Daily Log'!$D$2:$D$114,'Daily Log'!$A$2:$A$114,">="&A11,'Daily Log'!$A$2:$A$114,"<"&(A11+7)),"") | F11: =IF(C11="","",IF(C11<=-0.5,"On pace",IF(C11>0,"Check adherence","Slower than target"))) | G11: =Targets!$B$7 | H11: =Targets!$B$12 | I11: =Targets!$B$13
A12: 46313 | B12: =IFERROR(AVERAGEIFS('Daily Log'!$B$2:$B$114,'Daily Log'!$A$2:$A$114,">="&A12,'Daily Log'!$A$2:$A$114,"<"&(A12+7)),"") | C12: =IF(OR(B12="",B11=""),"",B12-B11) | D12: =IFERROR(AVERAGEIFS('Daily Log'!$C$2:$C$114,'Daily Log'!$A$2:$A$114,">="&A12,'Daily Log'!$A$2:$A$114,"<"&(A12+7)),"") | E12: =IFERROR(AVERAGEIFS('Daily Log'!$D$2:$D$114,'Daily Log'!$A$2:$A$114,">="&A12,'Daily Log'!$A$2:$A$114,"<"&(A12+7)),"") | F12: =IF(C12="","",IF(C12<=-0.5,"On pace",IF(C12>0,"Check adherence","Slower than target"))) | G12: =Targets!$B$7 | H12: =Targets!$B$12 | I12: =Targets!$B$13
A13: 46320 | B13: =IFERROR(AVERAGEIFS('Daily Log'!$B$2:$B$114,'Daily Log'!$A$2:$A$114,">="&A13,'Daily Log'!$A$2:$A$114,"<"&(A13+7)),"") | C13: =IF(OR(B13="",B12=""),"",B13-B12) | D13: =IFERROR(AVERAGEIFS('Daily Log'!$C$2:$C$114,'Daily Log'!$A$2:$A$114,">="&A13,'Daily Log'!$A$2:$A$114,"<"&(A13+7)),"") | E13: =IFERROR(AVERAGEIFS('Daily Log'!$D$2:$D$114,'Daily Log'!$A$2:$A$114,">="&A13,'Daily Log'!$A$2:$A$114,"<"&(A13+7)),"") | F13: =IF(C13="","",IF(C13<=-0.5,"On pace",IF(C13>0,"Check adherence","Slower than target"))) | G13: =Targets!$B$7 | H13: =Targets!$B$12 | I13: =Targets!$B$13
A14: 46327 | B14: =IFERROR(AVERAGEIFS('Daily Log'!$B$2:$B$114,'Daily Log'!$A$2:$A$114,">="&A14,'Daily Log'!$A$2:$A$114,"<"&(A14+7)),"") | C14: =IF(OR(B14="",B13=""),"",B14-B13) | D14: =IFERROR(AVERAGEIFS('Daily Log'!$C$2:$C$114,'Daily Log'!$A$2:$A$114,">="&A14,'Daily Log'!$A$2:$A$114,"<"&(A14+7)),"") | E14: =IFERROR(AVERAGEIFS('Daily Log'!$D$2:$D$114,'Daily Log'!$A$2:$A$114,">="&A14,'Daily Log'!$A$2:$A$114,"<"&(A14+7)),"") | F14: =IF(C14="","",IF(C14<=-0.5,"On pace",IF(C14>0,"Check adherence","Slower than target"))) | G14: =Targets!$B$7 | H14: =Targets!$B$12 | I14: =Targets!$B$13
... A17: 46348 | B17: =IFERROR(AVERAGEIFS('Daily Log'!$B$2:$B$114,'Daily Log'!$A$2:$A$114,">="&A17,'Daily Log'!$A$2:$A$114,"<"&(A17+7)),"") | C17: =IF(OR(B17="",B16=""),"",B17-B16) | D17: =IFERROR(AVERAGEIFS('Daily Log'!$C$2:$C$114,'Daily Log'!$A$2:$A$114,">="&A17,'Daily Log'!$A$2:$A$114,"<"&(A17+7)),"") | E17: =IFERROR(AVERAGEIFS('Daily Log'!$D$2:$D$114,'Daily Log'!$A$2:$A$114,">="&A17,'Daily Log'!$A$2:$A$114,"<"&(A17+7)),"") | F17: =IF(C17="","",IF(C17<=-0.5,"On pace",IF(C17>0,"Check adherence","Slower than target"))) | G17: =Targets!$B$7 | H17: =Targets!$B$12 | I17: =Targets!$B$13

Sheet Training & Recovery
A1: Training & Recovery
A2: Ring + Tonal, logged from screenshots. Blue = you fill in. Sleep hours blank until the ring actually syncs a night.
A4: Date | B4: Sleep (hrs) | C4: Resting HR | D4: HRV (ms) | E4: SpO2 (%) | F4: BP Sys | G4: BP Dia | H4: Tonal Volume (lbs) | I4: Tonal Duration (min) | J4: Notes | K4: 7-day Avg RHR | L4: 7-day Avg HRV | M4: Steps
A5: 46249 | C5: 84 | D5: 128 | E5: 98 | F5: 129 | G5: 89 | J5: Ring (generic/TK5) synced mid-day, sleep not yet recorded. Tonal: mid-session screenshot (Standing Single-Arm Row -> Standing Chest Press) — send the end-of-workout summary screen for full volume/duration/calories. | K5: =IFERROR(AVERAGEIFS($C$5:$C5,$A$5:$A5,">="&(A5-6),$A$5:$A5,"<="&A5),"") | L5: =IFERROR(AVERAGEIFS($D$5:$D5,$A$5:$A5,">="&(A5-6),$A$5:$A5,"<="&A5),"")
A6: 46250 | K6: =IFERROR(AVERAGEIFS($C$5:$C6,$A$5:$A6,">="&(A6-6),$A$5:$A6,"<="&A6),"") | L6: =IFERROR(AVERAGEIFS($D$5:$D6,$A$5:$A6,">="&(A6-6),$A$5:$A6,"<="&A6),"")
A7: 46251 | K7: =IFERROR(AVERAGEIFS($C$5:$C7,$A$5:$A7,">="&(A7-6),$A$5:$A7,"<="&A7),"") | L7: =IFERROR(AVERAGEIFS($D$5:$D7,$A$5:$A7,">="&(A7-6),$A$5:$A7,"<="&A7),"")
A8: 46252 | K8: =IFERROR(AVERAGEIFS($C$5:$C8,$A$5:$A8,">="&(A8-6),$A$5:$A8,"<="&A8),"") | L8: =IFERROR(AVERAGEIFS($D$5:$D8,$A$5:$A8,">="&(A8-6),$A$5:$A8,"<="&A8),"")
A9: 46253 | H9: 4792 | I9: 14.3 | J9: Tonal end-of-workout summary, 7:20pm. Volume 4,792 lbs, Duration 14:16, Movement Target 100%, Calories Burned 101, Work 9.8 kJ, Time Under Tension 6:06, Coaching Cues 0. Strong volume day - highest of the Last-8-Days view (Fri 4,960 lbs, Sat 4,438 lbs, today 4,792 lbs). | K9: =IFERROR(AVERAGEIFS($C$5:$C9,$A$5:$A9,">="&(A9-6),$A$5:$A9,"<="&A9),"") | L9: =IFERROR(AVERAGEIFS($D$5:$D9,$A$5:$A9,">="&(A9-6),$A$5:$A9,"<="&A9),"")
A10: 46254 | K10: =IFERROR(AVERAGEIFS($C$5:$C10,$A$5:$A10,">="&(A10-6),$A$5:$A10,"<="&A10),"") | L10: =IFERROR(AVERAGEIFS($D$5:$D10,$A$5:$A10,">="&(A10-6),$A$5:$A10,"<="&A10),"")
A11: 46255 | K11: =IFERROR(AVERAGEIFS($C$5:$C11,$A$5:$A11,">="&(A11-6),$A$5:$A11,"<="&A11),"") | L11: =IFERROR(AVERAGEIFS($D$5:$D11,$A$5:$A11,">="&(A11-6),$A$5:$A11,"<="&A11),"")
A12: 46256 | K12: =IFERROR(AVERAGEIFS($C$5:$C12,$A$5:$A12,">="&(A12-6),$A$5:$A12,"<="&A12),"") | L12: =IFERROR(AVERAGEIFS($D$5:$D12,$A$5:$A12,">="&(A12-6),$A$5:$A12,"<="&A12),"")
A13: 46257 | K13: =IFERROR(AVERAGEIFS($C$5:$C13,$A$5:$A13,">="&(A13-6),$A$5:$A13,"<="&A13),"") | L13: =IFERROR(AVERAGEIFS($D$5:$D13,$A$5:$A13,">="&(A13-6),$A$5:$A13,"<="&A13),"")
A14: 46258 | K14: =IFERROR(AVERAGEIFS($C$5:$C14,$A$5:$A14,">="&(A14-6),$A$5:$A14,"<="&A14),"") | L14: =IFERROR(AVERAGEIFS($D$5:$D14,$A$5:$A14,">="&(A14-6),$A$5:$A14,"<="&A14),"")
A15: 46259 | K15: =IFERROR(AVERAGEIFS($C$5:$C15,$A$5:$A15,">="&(A15-6),$A$5:$A15,"<="&A15),"") | L15: =IFERROR(AVERAGEIFS($D$5:$D15,$A$5:$A15,">="&(A15-6),$A$5:$A15,"<="&A15),"")
A16: 46260 | K16: =IFERROR(AVERAGEIFS($C$5:$C16,$A$5:$A16,">="&(A16-6),$A$5:$A16,"<="&A16),"") | L16: =IFERROR(AVERAGEIFS($D$5:$D16,$A$5:$A16,">="&(A16-6),$A$5:$A16,"<="&A16),"")
A17: 46261 | K17: =IFERROR(AVERAGEIFS($C$5:$C17,$A$5:$A17,">="&(A17-6),$A$5:$A17,"<="&A17),"") | L17: =IFERROR(AVERAGEIFS($D$5:$D17,$A$5:$A17,">="&(A17-6),$A$5:$A17,"<="&A17),"")
A18: 46262 | K18: =IFERROR(AVERAGEIFS($C$5:$C18,$A$5:$A18,">="&(A18-6),$A$5:$A18,"<="&A18),"") | L18: =IFERROR(AVERAGEIFS($D$5:$D18,$A$5:$A18,">="&(A18-6),$A$5:$A18,"<="&A18),"")
A19: 46263 | K19: =IFERROR(AVERAGEIFS($C$5:$C19,$A$5:$A19,">="&(A19-6),$A$5:$A19,"<="&A19),"") | L19: =IFERROR(AVERAGEIFS($D$5:$D19,$A$5:$A19,">="&(A19-6),$A$5:$A19,"<="&A19),"")
A20: 46264 | K20: =IFERROR(AVERAGEIFS($C$5:$C20,$A$5:$A20,">="&(A20-6),$A$5:$A20,"<="&A20),"") | L20: =IFERROR(AVERAGEIFS($D$5:$D20,$A$5:$A20,">="&(A20-6),$A$5:$A20,"<="&A20),"")
A21: 46265 | K21: =IFERROR(AVERAGEIFS($C$5:$C21,$A$5:$A21,">="&(A21-6),$A$5:$A21,"<="&A21),"") | L21: =IFERROR(AVERAGEIFS($D$5:$D21,$A$5:$A21,">="&(A21-6),$A$5:$A21,"<="&A21),"")
... A37: 46281 | K37: =IFERROR(AVERAGEIFS($C$5:$C37,$A$5:$A37,">="&(A37-6),$A$5:$A37,"<="&A37),"") | L37: =IFERROR(AVERAGEIFS($D$5:$D37,$A$5:$A37,">="&(A37-6),$A$5:$A37,"<="&A37),"")
A38: Field Status | K38: =IFERROR(AVERAGEIFS($C$5:$C38,$A$5:$A38,">="&(A38-6),$A$5:$A38,"<="&A38),"") | L38: =IFERROR(AVERAGEIFS($D$5:$D38,$A$5:$A38,">="&(A38-6),$A$5:$A38,"<="&A38),"")
A39: Supplementary fields only — core nutrition/weight logging is never questioned. A field silent 10+ days flips to "REVIEW", which means: ask Roberto whether to keep watching for it or retire it from the dashboard. | K39: =IFERROR(AVERAGEIFS($C$5:$C39,$A$5:$A39,">="&(A39-6),$A$5:$A39,"<="&A39),"") | L39: =IFERROR(AVERAGEIFS($D$5:$D39,$A$5:$A39,">="&(A39-6),$A$5:$A39,"<="&A39),"")
A40: 46284 | K40: =IFERROR(AVERAGEIFS($C$5:$C40,$A$5:$A40,">="&(A40-6),$A$5:$A40,"<="&A40),"") | L40: =IFERROR(AVERAGEIFS($D$5:$D40,$A$5:$A40,">="&(A40-6),$A$5:$A40,"<="&A40),"")
A41: Field | B41: Last Logged | C41: Days Idle | D41: Status | K41: =IFERROR(AVERAGEIFS($C$5:$C41,$A$5:$A41,">="&(A41-6),$A$5:$A41,"<="&A41),"") | L41: =IFERROR(AVERAGEIFS($D$5:$D41,$A$5:$A41,">="&(A41-6),$A$5:$A41,"<="&A41),"")
A42: Recovery Reading (ring) | B42: =IFERROR(_xlfn.MAXIFS($A$5:$A$34,$C$5:$C$34,"<>"),"") | C42: =IF(B42="","",TODAY()-B42) | D42: =IF(B42="","no data yet",IF(C42>=10,"REVIEW — ask Roberto","Active")) | K42: =IFERROR(AVERAGEIFS($C$5:$C42,$A$5:$A42,">="&(A42-6),$A$5:$A42,"<="&A42),"") | L42: =IFERROR(AVERAGEIFS($D$5:$D42,$A$5:$A42,">="&(A42-6),$A$5:$A42,"<="&A42),"")
A43: Steps | B43: =IFERROR(_xlfn.MAXIFS($A$5:$A$34,$M$5:$M$34,"<>"),"") | C43: =IF(B43="","",TODAY()-B43) | D43: =IF(B43="","no data yet",IF(C43>=10,"REVIEW — ask Roberto","Active")) | K43: =IFERROR(AVERAGEIFS($C$5:$C43,$A$5:$A43,">="&(A43-6),$A$5:$A43,"<="&A43),"") | L43: =IFERROR(AVERAGEIFS($D$5:$D43,$A$5:$A43,">="&(A43-6),$A$5:$A43,"<="&A43),"")
A44: Tonal Training | B44: =IFERROR(_xlfn.MAXIFS($A$5:$A$34,$H$5:$H$34,"<>"),"") | C44: =IF(B44="","",TODAY()-B44) | D44: =IF(B44="","no data yet",IF(C44>=10,"REVIEW — ask Roberto","Active")) | K44: =IFERROR(AVERAGEIFS($C$5:$C44,$A$5:$A44,">="&(A44-6),$A$5:$A44,"<="&A44),"") | L44: =IFERROR(AVERAGEIFS($D$5:$D44,$A$5:$A44,">="&(A44-6),$A$5:$A44,"<="&A44),"")
A45: Bloodwork | B45: =IFERROR(IF(MAX(Bloodwork!$A$5:$A$16)=0,"",MAX(Bloodwork!$A$5:$A$16)),"") | C45: =IF(B45="","",TODAY()-B45) | D45: =IF(B45="","no data yet",IF(C45>=10,"REVIEW — ask Roberto","Active")) | K45: =IFERROR(AVERAGEIFS($C$5:$C45,$A$5:$A45,">="&(A45-6),$A$5:$A45,"<="&A45),"") | L45: =IFERROR(AVERAGEIFS($D$5:$D45,$A$5:$A45,">="&(A45-6),$A$5:$A45,"<="&A45),"")
A46: 46290 | C46: Field | D46: Last Logged | E46: Days Idle | F46: Status | K46: =IFERROR(AVERAGEIFS($C$5:$C46,$A$5:$A46,">="&(A46-6),$A$5:$A46,"<="&A46),"") | L46: =IFERROR(AVERAGEIFS($D$5:$D46,$A$5:$A46,">="&(A46-6),$A$5:$A46,"<="&A46),"")
A47: 46291 | C47: Waist | D47: =IFERROR(_xlfn.MAXIFS('Daily Log'!$A$2:$A$200,'Daily Log'!$N$2:$N$200,"<>"),"") | E47: =IF(D47="","",TODAY()-D47) | F47: =IF(D47="","no data yet",IF(E47>=10,"REVIEW — ask Roberto","Active")) | K47: =IFERROR(AVERAGEIFS($C$5:$C47,$A$5:$A47,">="&(A47-6),$A$5:$A47,"<="&A47),"") | L47: =IFERROR(AVERAGEIFS($D$5:$D47,$A$5:$A47,">="&(A47-6),$A$5:$A47,"<="&A47),"")
A48: 46292 | K48: =IFERROR(AVERAGEIFS($C$5:$C48,$A$5:$A48,">="&(A48-6),$A$5:$A48,"<="&A48),"") | L48: =IFERROR(AVERAGEIFS($D$5:$D48,$A$5:$A48,">="&(A48-6),$A$5:$A48,"<="&A48),"")
A49: 46293 | K49: =IFERROR(AVERAGEIFS($C$5:$C49,$A$5:$A49,">="&(A49-6),$A$5:$A49,"<="&A49),"") | L49: =IFERROR(AVERAGEIFS($D$5:$D49,$A$5:$A49,">="&(A49-6),$A$5:$A49,"<="&A49),"")
A50: 46294 | K50: =IFERROR(AVERAGEIFS($C$5:$C50,$A$5:$A50,">="&(A50-6),$A$5:$A50,"<="&A50),"") | L50: =IFERROR(AVERAGEIFS($D$5:$D50,$A$5:$A50,">="&(A50-6),$A$5:$A50,"<="&A50),"")
A51: 46295 | K51: =IFERROR(AVERAGEIFS($C$5:$C51,$A$5:$A51,">="&(A51-6),$A$5:$A51,"<="&A51),"") | L51: =IFERROR(AVERAGEIFS($D$5:$D51,$A$5:$A51,">="&(A51-6),$A$5:$A51,"<="&A51),"")
A52: 46296 | K52: =IFERROR(AVERAGEIFS($C$5:$C52,$A$5:$A52,">="&(A52-6),$A$5:$A52,"<="&A52),"") | L52: =IFERROR(AVERAGEIFS($D$5:$D52,$A$5:$A52,">="&(A52-6),$A$5:$A52,"<="&A52),"")
A53: 46297 | K53: =IFERROR(AVERAGEIFS($C$5:$C53,$A$5:$A53,">="&(A53-6),$A$5:$A53,"<="&A53),"") | L53: =IFERROR(AVERAGEIFS($D$5:$D53,$A$5:$A53,">="&(A53-6),$A$5:$A53,"<="&A53),"")
A54: 46298 | K54: =IFERROR(AVERAGEIFS($C$5:$C54,$A$5:$A54,">="&(A54-6),$A$5:$A54,"<="&A54),"") | L54: =IFERROR(AVERAGEIFS($D$5:$D54,$A$5:$A54,">="&(A54-6),$A$5:$A54,"<="&A54),"")
A55: 46299 | K55: =IFERROR(AVERAGEIFS($C$5:$C55,$A$5:$A55,">="&(A55-6),$A$5:$A55,"<="&A55),"") | L55: =IFERROR(AVERAGEIFS($D$5:$D55,$A$5:$A55,">="&(A55-6),$A$5:$A55,"<="&A55),"")
A56: 46300 | K56: =IFERROR(AVERAGEIFS($C$5:$C56,$A$5:$A56,">="&(A56-6),$A$5:$A56,"<="&A56),"") | L56: =IFERROR(AVERAGEIFS($D$5:$D56,$A$5:$A56,">="&(A56-6),$A$5:$A56,"<="&A56),"")
...

Sheet Advisory Board Log
A1: Advisory Board Log
A2: 1 = flagged something that day, 0 = approved, nothing to flag. Only real evaluated days get a row — nothing pre-filled ahead of time.
A4: Date | B4: Mark Hyman | C4: Benjamin Bikman | D4: Rena Malik | E4: Brad Schoenfeld | F4: Peter Attia | G4: Gary Brecka | H4: Andy Galpin | I4: Layne Norton | J4: Andrew Huberman | K4: Arthur C. Brooks | L4: Chip Conley | M4: William Li | N4: Jessie Inchauspe
A5: 46249 | B5: 1 | C5: 1 | D5: 1 | E5: 1 | F5: 1 | G5: 1 | H5: 0 | I5: 0 | J5: 0 | K5: 0 | L5: 0 | M5: 1
A6: 46250 | B6: 0 | C6: 0 | D6: 0 | E6: 0 | F6: 1 | G6: 0 | H6: 0 | I6: 1 | J6: 0 | K6: 0 | L6: 0 | M6: 0 | N6: 0
A7: 46251 | B7: 0 | C7: 1 | D7: 0 | E7: 0 | F7: 1 | G7: 0 | H7: 0 | I7: 0 | J7: 0 | K7: 0 | L7: 0 | M7: 0 | N7: 0
A38: Board Status
A39: Updates automatically as rows are added above. "Review" only triggers after 10 real logged days exist — never before. | C39: Days logged so far: | D39: =COUNT($A$5:$A$34)
A41: Advisor | B41: Last Flagged | C41: Days Silent | D41: Status
A42: Mark Hyman | B42: =IFERROR(_xlfn.MAXIFS($A$5:$A$34,B$5:B$34,1),"") | C42: =IF(B42="",IF($D$39>=1,TODAY()-INDEX($A$5:$A$34,1),""),TODAY()-B42) | D42: Retired 2026-08-18 (history preserved)
A43: Benjamin Bikman | B43: =IFERROR(_xlfn.MAXIFS($A$5:$A$34,C$5:C$34,1),"") | C43: =IF(B43="",IF($D$39>=1,TODAY()-INDEX($A$5:$A$34,1),""),TODAY()-B43) | D43: =IF($D$39<10,"Collecting data",IF(C43>=10,"REVIEW — notify Roberto","Active"))
A44: Rena Malik | B44: =IFERROR(_xlfn.MAXIFS($A$5:$A$34,D$5:D$34,1),"") | C44: =IF(B44="",IF($D$39>=1,TODAY()-INDEX($A$5:$A$34,1),""),TODAY()-B44) | D44: Retired 2026-08-18 (history preserved)
A45: Brad Schoenfeld | B45: =IFERROR(_xlfn.MAXIFS($A$5:$A$34,E$5:E$34,1),"") | C45: =IF(B45="",IF($D$39>=1,TODAY()-INDEX($A$5:$A$34,1),""),TODAY()-B45) | D45: =IF($D$39<10,"Collecting data",IF(C45>=10,"REVIEW — notify Roberto","Active"))
A46: Peter Attia | B46: =IFERROR(_xlfn.MAXIFS($A$5:$A$34,F$5:F$34,1),"") | C46: =IF(B46="",IF($D$39>=1,TODAY()-INDEX($A$5:$A$34,1),""),TODAY()-B46) | D46: =IF($D$39<10,"Collecting data",IF(C46>=10,"REVIEW — notify Roberto","Active"))
A47: Gary Brecka | B47: =IFERROR(_xlfn.MAXIFS($A$5:$A$34,G$5:G$34,1),"") | C47: =IF(B47="",IF($D$39>=1,TODAY()-INDEX($A$5:$A$34,1),""),TODAY()-B47) | D47: =IF($D$39<10,"Collecting data",IF(C47>=10,"REVIEW — notify Roberto","Active"))
A48: Andy Galpin | B48: =IFERROR(_xlfn.MAXIFS($A$5:$A$34,H$5:H$34,1),"") | C48: =IF(B48="",IF($D$39>=1,TODAY()-INDEX($A$5:$A$34,1),""),TODAY()-B48) | D48: Retired 2026-08-18 (history preserved)
A49: Layne Norton | B49: =IFERROR(_xlfn.MAXIFS($A$5:$A$34,I$5:I$34,1),"") | C49: =IF(B49="",IF($D$39>=1,TODAY()-INDEX($A$5:$A$34,1),""),TODAY()-B49) | D49: =IF($D$39<10,"Collecting data",IF(C49>=10,"REVIEW — notify Roberto","Active"))
A50: Andrew Huberman | B50: =IFERROR(_xlfn.MAXIFS($A$5:$A$34,J$5:J$34,1),"") | C50: =IF(B50="",IF($D$39>=1,TODAY()-INDEX($A$5:$A$34,1),""),TODAY()-B50) | D50: =IF($D$39<10,"Collecting data",IF(C50>=10,"REVIEW — notify Roberto","Active"))
A51: Arthur C. Brooks | B51: =IFERROR(_xlfn.MAXIFS($A$5:$A$34,K$5:K$34,1),"") | C51: =IF(B51="",IF($D$39>=1,TODAY()-INDEX($A$5:$A$34,1),""),TODAY()-B51) | D51: Retired 2026-08-18 (history preserved)
A52: Chip Conley | B52: =IFERROR(_xlfn.MAXIFS($A$5:$A$34,L$5:L$34,1),"") | C52: =IF(B52="",IF($D$39>=1,TODAY()-INDEX($A$5:$A$34,1),""),TODAY()-B52) | D52: Retired 2026-08-18 (history preserved)
A53: William Li | B53: =IFERROR(_xlfn.MAXIFS($A$5:$A$34,M$5:M$34,1),"") | C53: =IF(B53="",IF($D$39>=1,TODAY()-INDEX($A$5:$A$34,1),""),TODAY()-B53) | D53: Retired 2026-08-18 (history preserved)
A54: Jessie Inchauspe | B54: =IFERROR(_xlfn.MAXIFS($A$5:$A$34,N$5:N$34,1),"") | C54: =IF(B54="",IF($D$39>=1,TODAY()-INDEX($A$5:$A$34,1),""),TODAY()-B54) | D54: Retired 2026-08-18 (history preserved)

Sheet Bloodwork
A1: Bloodwork
A2: One row per panel drawn. Blank until real results land — nothing pre-filled or estimated. First panel expected ~2026-08-26.
A4: Date Drawn | B4: Total Chol | C4: LDL | D4: HDL | E4: Triglycerides | F4: ApoB | G4: hs-CRP | H4: A1C | I4: Fasting Glucose | J4: Vitamin D | K4: Testosterone | L4: Notes
A5: 2026-08-13 | B5: N/A | C5: N/A | D5: N/A | E5: N/A | F5: 130 | G5: 0.84 | H5: 5.6 | I5: 104 | J5: 30.8 | K5: 631 | L5: FINAL LabCorp panel (collected 8/13, finalized 8/19). No lipid panel (Chol/LDL/HDL/Trig) drawn this round. ApoB 130 mg/dL - flagged HIGH by lab (desirable <90, high 100-130, very high >130) - this is the headline finding: ApoB is the primary cardiovascular risk marker in the Attia-influenced coaching style this dashboard uses, and 130 sits at the top of the High band. Cardiac hs-CRP 0.84 mg/L - Low risk (<1.00), good news, low inflammation. IGF-1 167 ng/mL - normal (ref 64-240). Glucose 104 mg/dL flagged High, fasting status not recorded - not conclusive alone. A1C 5.6% at top of normal. Vitamin D 30.8, testosterone 631 (free 10.2) - both normal. TSH/T4/kidney/liver/CBC all in range. Flag ApoB + glucose to Dr. Aldrich - not medical advice.

Sheet Monthly Summary
A1: Month | B1: Avg Weight (lb) | C1: Weight Change vs Prior Month | D1: Avg Calories | E1: Avg Protein (g) | F1: Days Logged | G1: Days On Target (±100 kcal)
A2: 46235 | B2: =IFERROR(AVERAGEIFS('Daily Log'!$B$2:$B$114,'Daily Log'!$A$2:$A$114,">="&A2,'Daily Log'!$A$2:$A$114,"<"&(EOMONTH(A2,0)+1)),"") | D2: =IFERROR(AVERAGEIFS('Daily Log'!$C$2:$C$114,'Daily Log'!$A$2:$A$114,">="&A2,'Daily Log'!$A$2:$A$114,"<"&(EOMONTH(A2,0)+1)),"") | E2: =IFERROR(AVERAGEIFS('Daily Log'!$D$2:$D$114,'Daily Log'!$A$2:$A$114,">="&A2,'Daily Log'!$A$2:$A$114,"<"&(EOMONTH(A2,0)+1)),"") | F2: =COUNTIFS('Daily Log'!$A$2:$A$114,">="&A2,'Daily Log'!$A$2:$A$114,"<"&(EOMONTH(A2,0)+1),'Daily Log'!$C$2:$C$114,"<>") | G2: =COUNTIFS('Daily Log'!$A$2:$A$114,">="&A2,'Daily Log'!$A$2:$A$114,"<"&(EOMONTH(A2,0)+1),'Daily Log'!$C$2:$C$114,">="&(Targets!$B$12-100),'Daily Log'!$C$2:$C$114,"<="&(Targets!$B$12+100))
A3: 46266 | B3: =IFERROR(AVERAGEIFS('Daily Log'!$B$2:$B$114,'Daily Log'!$A$2:$A$114,">="&A3,'Daily Log'!$A$2:$A$114,"<"&(EOMONTH(A3,0)+1)),"") | C3: =IF(OR(B3="",B2=""),"",B3-B2) | D3: =IFERROR(AVERAGEIFS('Daily Log'!$C$2:$C$114,'Daily Log'!$A$2:$A$114,">="&A3,'Daily Log'!$A$2:$A$114,"<"&(EOMONTH(A3,0)+1)),"") | E3: =IFERROR(AVERAGEIFS('Daily Log'!$D$2:$D$114,'Daily Log'!$A$2:$A$114,">="&A3,'Daily Log'!$A$2:$A$114,"<"&(EOMONTH(A3,0)+1)),"") | F3: =COUNTIFS('Daily Log'!$A$2:$A$114,">="&A3,'Daily Log'!$A$2:$A$114,"<"&(EOMONTH(A3,0)+1),'Daily Log'!$C$2:$C$114,"<>") | G3: =COUNTIFS('Daily Log'!$A$2:$A$114,">="&A3,'Daily Log'!$A$2:$A$114,"<"&(EOMONTH(A3,0)+1),'Daily Log'!$C$2:$C$114,">="&(Targets!$B$12-100),'Daily Log'!$C$2:$C$114,"<="&(Targets!$B$12+100))
A4: 46296 | B4: =IFERROR(AVERAGEIFS('Daily Log'!$B$2:$B$114,'Daily Log'!$A$2:$A$114,">="&A4,'Daily Log'!$A$2:$A$114,"<"&(EOMONTH(A4,0)+1)),"") | C4: =IF(OR(B4="",B3=""),"",B4-B3) | D4: =IFERROR(AVERAGEIFS('Daily Log'!$C$2:$C$114,'Daily Log'!$A$2:$A$114,">="&A4,'Daily Log'!$A$2:$A$114,"<"&(EOMONTH(A4,0)+1)),"") | E4: =IFERROR(AVERAGEIFS('Daily Log'!$D$2:$D$114,'Daily Log'!$A$2:$A$114,">="&A4,'Daily Log'!$A$2:$A$114,"<"&(EOMONTH(A4,0)+1)),"") | F4: =COUNTIFS('Daily Log'!$A$2:$A$114,">="&A4,'Daily Log'!$A$2:$A$114,"<"&(EOMONTH(A4,0)+1),'Daily Log'!$C$2:$C$114,"<>") | G4: =COUNTIFS('Daily Log'!$A$2:$A$114,">="&A4,'Daily Log'!$A$2:$A$114,"<"&(EOMONTH(A4,0)+1),'Daily Log'!$C$2:$C$114,">="&(Targets!$B$12-100),'Daily Log'!$C$2:$C$114,"<="&(Targets!$B$12+100))
A5: 46327 | B5: =IFERROR(AVERAGEIFS('Daily Log'!$B$2:$B$114,'Daily Log'!$A$2:$A$114,">="&A5,'Daily Log'!$A$2:$A$114,"<"&(EOMONTH(A5,0)+1)),"") | C5: =IF(OR(B5="",B4=""),"",B5-B4) | D5: =IFERROR(AVERAGEIFS('Daily Log'!$C$2:$C$114,'Daily Log'!$A$2:$A$114,">="&A5,'Daily Log'!$A$2:$A$114,"<"&(EOMONTH(A5,0)+1)),"") | E5: =IFERROR(AVERAGEIFS('Daily Log'!$D$2:$D$114,'Daily Log'!$A$2:$A$114,">="&A5,'Daily Log'!$A$2:$A$114,"<"&(EOMONTH(A5,0)+1)),"") | F5: =COUNTIFS('Daily Log'!$A$2:$A$114,">="&A5,'Daily Log'!$A$2:$A$114,"<"&(EOMONTH(A5,0)+1),'Daily Log'!$C$2:$C$114,"<>") | G5: =COUNTIFS('Daily Log'!$A$2:$A$114,">="&A5,'Daily Log'!$A$2:$A$114,"<"&(EOMONTH(A5,0)+1),'Daily Log'!$C$2:$C$114,">="&(Targets!$B$12-100),'Daily Log'!$C$2:$C$114,"<="&(Targets!$B$12+100))
A6: 46357 | B6: =IFERROR(AVERAGEIFS('Daily Log'!$B$2:$B$114,'Daily Log'!$A$2:$A$114,">="&A6,'Daily Log'!$A$2:$A$114,"<"&(EOMONTH(A6,0)+1)),"") | C6: =IF(OR(B6="",B5=""),"",B6-B5) | D6: =IFERROR(AVERAGEIFS('Daily Log'!$C$2:$C$114,'Daily Log'!$A$2:$A$114,">="&A6,'Daily Log'!$A$2:$A$114,"<"&(EOMONTH(A6,0)+1)),"") | E6: =IFERROR(AVERAGEIFS('Daily Log'!$D$2:$D$114,'Daily Log'!$A$2:$A$114,">="&A6,'Daily Log'!$A$2:$A$114,"<"&(EOMONTH(A6,0)+1)),"") | F6: =COUNTIFS('Daily Log'!$A$2:$A$114,">="&A6,'Daily Log'!$A$2:$A$114,"<"&(EOMONTH(A6,0)+1),'Daily Log'!$C$2:$C$114,"<>") | G6: =COUNTIFS('Daily Log'!$A$2:$A$114,">="&A6,'Daily Log'!$A$2:$A$114,"<"&(EOMONTH(A6,0)+1),'Daily Log'!$C$2:$C$114,">="&(Targets!$B$12-100),'Daily Log'!$C$2:$C$114,"<="&(Targets!$B$12+100))
